Failure # 1 (occurred at 2021-05-20_22-28-43)
Traceback (most recent call last):
  File "/home/nicolai/.local/lib/python3.8/site-packages/ray/tune/trial_runner.py", line 702, in _process_trial
    results = self.trial_executor.fetch_result(trial)
  File "/home/nicolai/.local/lib/python3.8/site-packages/ray/tune/ray_trial_executor.py", line 686, in fetch_result
    result = ray.get(trial_future[0], timeout=DEFAULT_GET_TIMEOUT)
  File "/home/nicolai/.local/lib/python3.8/site-packages/ray/_private/client_mode_hook.py", line 47, in wrapper
    return func(*args, **kwargs)
  File "/home/nicolai/.local/lib/python3.8/site-packages/ray/worker.py", line 1483, in get
    raise value
ray.exceptions.RayActorError: The actor died because of an error raised in its creation task, [36mray::PPO.__init__()[39m (pid=181, ip=192.168.1.14)
  File "python/ray/_raylet.pyx", line 505, in ray._raylet.execute_task
  File "python/ray/_raylet.pyx", line 449, in ray._raylet.execute_task.function_executor
  File "/home/nicolai/.local/lib/python3.8/site-packages/ray/_private/function_manager.py", line 556, in actor_method_executor
    return method(__ray_actor, *args, **kwargs)
  File "/home/nicolai/.local/lib/python3.8/site-packages/ray/rllib/agents/trainer_template.py", line 121, in __init__
    Trainer.__init__(self, config, env, logger_creator)
  File "/home/nicolai/.local/lib/python3.8/site-packages/ray/rllib/agents/trainer.py", line 516, in __init__
    super().__init__(config, logger_creator)
  File "/home/nicolai/.local/lib/python3.8/site-packages/ray/tune/trainable.py", line 98, in __init__
    self.setup(copy.deepcopy(self.config))
  File "/home/nicolai/.local/lib/python3.8/site-packages/ray/rllib/agents/trainer.py", line 707, in setup
    self._init(self.config, self.env_creator)
  File "/home/nicolai/.local/lib/python3.8/site-packages/ray/rllib/agents/trainer_template.py", line 148, in _init
    self.workers = self._make_workers(
  File "/home/nicolai/.local/lib/python3.8/site-packages/ray/rllib/agents/trainer.py", line 783, in _make_workers
    return WorkerSet(
  File "/home/nicolai/.local/lib/python3.8/site-packages/ray/rllib/evaluation/worker_set.py", line 90, in __init__
    self._local_worker = self._make_worker(
  File "/home/nicolai/.local/lib/python3.8/site-packages/ray/rllib/evaluation/worker_set.py", line 317, in _make_worker
    worker = cls(
  File "/home/nicolai/.local/lib/python3.8/site-packages/ray/rllib/evaluation/rollout_worker.py", line 383, in __init__
    self.env = _validate_env(env_creator(env_context))
  File "main.py", line 35, in env_creator
    level_file_paths = absolute_file_paths('./levels_manual')
  File "main.py", line 26, in absolute_file_paths
    return [entry.path for entry in os.scandir(path) if entry.is_file()]
FileNotFoundError: [Errno 2] No such file or directory: '/mnt/c/users/nicol/OneDrive/Dokumenter/DTU/02285 Kunstig intelligens og multiagent-systemer/project/ckpt/PPO/PPO_multi_agent_env_f7463_00000_0_lr=0.0001_2021-05-20_22-28-41/levels_manual'

