Failure # 1 (occurred at 2021-05-20_22-03-29)
Traceback (most recent call last):
  File "C:\Users\nicol\anaconda3\lib\site-packages\ray\tune\trial_runner.py", line 702, in _process_trial
    results = self.trial_executor.fetch_result(trial)
  File "C:\Users\nicol\anaconda3\lib\site-packages\ray\tune\ray_trial_executor.py", line 686, in fetch_result
    result = ray.get(trial_future[0], timeout=DEFAULT_GET_TIMEOUT)
  File "C:\Users\nicol\anaconda3\lib\site-packages\ray\_private\client_mode_hook.py", line 47, in wrapper
    return func(*args, **kwargs)
  File "C:\Users\nicol\anaconda3\lib\site-packages\ray\worker.py", line 1483, in get
    raise value
ray.exceptions.RayActorError: The actor died because of an error raised in its creation task, [36mray::PPO.__init__()[39m (pid=22776, ip=192.168.1.14)
  File "python\ray\_raylet.pyx", line 505, in ray._raylet.execute_task
  File "python\ray\_raylet.pyx", line 449, in ray._raylet.execute_task.function_executor
  File "C:\Users\nicol\anaconda3\lib\site-packages\ray\_private\function_manager.py", line 556, in actor_method_executor
    return method(__ray_actor, *args, **kwargs)
  File "C:\Users\nicol\anaconda3\lib\site-packages\ray\rllib\agents\trainer_template.py", line 121, in __init__
    Trainer.__init__(self, config, env, logger_creator)
  File "C:\Users\nicol\anaconda3\lib\site-packages\ray\rllib\agents\trainer.py", line 516, in __init__
    super().__init__(config, logger_creator)
  File "C:\Users\nicol\anaconda3\lib\site-packages\ray\tune\trainable.py", line 98, in __init__
    self.setup(copy.deepcopy(self.config))
  File "C:\Users\nicol\anaconda3\lib\site-packages\ray\rllib\agents\trainer.py", line 707, in setup
    self._init(self.config, self.env_creator)
  File "C:\Users\nicol\anaconda3\lib\site-packages\ray\rllib\agents\trainer_template.py", line 148, in _init
    self.workers = self._make_workers(
  File "C:\Users\nicol\anaconda3\lib\site-packages\ray\rllib\agents\trainer.py", line 783, in _make_workers
    return WorkerSet(
  File "C:\Users\nicol\anaconda3\lib\site-packages\ray\rllib\evaluation\worker_set.py", line 90, in __init__
    self._local_worker = self._make_worker(
  File "C:\Users\nicol\anaconda3\lib\site-packages\ray\rllib\evaluation\worker_set.py", line 317, in _make_worker
    worker = cls(
  File "C:\Users\nicol\anaconda3\lib\site-packages\ray\rllib\evaluation\rollout_worker.py", line 383, in __init__
    self.env = _validate_env(env_creator(env_context))
  File "C:/Users/nicol/OneDrive/Dokumenter/DTU/02285 Kunstig intelligens og multiagent-systemer/project/main.py", line 35, in env_creator
    level_file_paths = absolute_file_paths('./levels_manual')
  File "C:/Users/nicol/OneDrive/Dokumenter/DTU/02285 Kunstig intelligens og multiagent-systemer/project/main.py", line 26, in absolute_file_paths
    return [entry.path for entry in os.scandir(path) if entry.is_file()]
FileNotFoundError: [WinError 3] Den angivne sti blev ikke fundet: 'C:\\Users\\nicol\\OneDrive\\Dokumenter\\DTU\\02285 Kunstig intelligens og multiagent-systemer\\project\\ckpt\\PPO\\PPO_multi_agent_env_6f11b_00001_1_lr=0.0001_2021-05-20_22-03-24\\levels_manual'

